Error occured on this URL: https://www.amazon.com/gp/help/seller/at-a-glance.html/ref=dp_merchant_link?ie=UTF8&seller=A24GXYRVATLSKT
Traceback (most recent call last):
  File "C:\Users\Hp\Desktop\send to Helper\bot.py", line 181, in main_bot
    driver.find_element_by_xpath('//*[@id="sellerProfileTriggerId"]').click()
  File "C:\Python39\lib\site-packages\selenium\webdriver\remote\webelement.py", line 80, in click
    self._execute(Command.CLICK_ELEMENT)
  File "C:\Python39\lib\site-packages\selenium\webdriver\remote\webelement.py", line 633, in _execute
    return self._parent.execute(command, params)
  File "C:\Python39\lib\site-packages\selenium\webdriver\remote\webdriver.py", line 321, in execute
    self.error_handler.check_response(response)
  File "C:\Python39\lib\site-packages\selenium\webdriver\remote\errorhandler.py", line 242, in check_response
    raise exception_class(message, screen, stacktrace)
selenium.common.exceptions.ElementNotInteractableException: Message: element not interactable
  (Session info: chrome=92.0.4515.159)


During handling of the above exception, another exception occurred:

Traceback (most recent call last):
  File "C:\Users\Hp\Desktop\send to Helper\bot.py", line 183, in main_bot
    driver.get(driver.find_element_by_xpath('//*[@id="sellerProfileTriggerId"]').get_attribute('href'))
  File "C:\Python39\lib\site-packages\selenium\webdriver\remote\webdriver.py", line 333, in get
    self.execute(Command.GET, {'url': url})
  File "C:\Python39\lib\site-packages\selenium\webdriver\remote\webdriver.py", line 321, in execute
    self.error_handler.check_response(response)
  File "C:\Python39\lib\site-packages\selenium\webdriver\remote\errorhandler.py", line 242, in check_response
    raise exception_class(message, screen, stacktrace)
selenium.common.exceptions.WebDriverException: Message: unknown error: net::ERR_CONNECTION_CLOSED
  (Session info: chrome=92.0.4515.159)

