Error occured on this URL: https://www.amazon.com/
Traceback (most recent call last):
  File "C:\Users\Hp\Desktop\send to Helper\bot.py", line 121, in main_bot
    driver.get('https://www.amazon.com/')
  File "C:\Python39\lib\site-packages\selenium\webdriver\remote\webdriver.py", line 333, in get
    self.execute(Command.GET, {'url': url})
  File "C:\Python39\lib\site-packages\selenium\webdriver\remote\webdriver.py", line 321, in execute
    self.error_handler.check_response(response)
  File "C:\Python39\lib\site-packages\selenium\webdriver\remote\errorhandler.py", line 242, in check_response
    raise exception_class(message, screen, stacktrace)
selenium.common.exceptions.WebDriverException: Message: unknown error: net::ERR_NAME_NOT_RESOLVED
  (Session info: chrome=92.0.4515.159)

